2021-05-01 08:58:55,904 ERROR: Exception on / [GET] [in /home/ec2-user/.local/lib/python3.7/site-packages/flask/app.py:1761]
Traceback (most recent call last):
  File "/home/ec2-user/.local/lib/python3.7/site-packages/sqlalchemy/engine/base.py", line 1193, in _execute_context
    context)
  File "/home/ec2-user/.local/lib/python3.7/site-packages/sqlalchemy/engine/default.py", line 508, in do_execute
    cursor.execute(statement, parameters)
sqlite3.OperationalError: no such table: post

The above exception was the direct cause of the following exception:

Traceback (most recent call last):
  File "/home/ec2-user/.local/lib/python3.7/site-packages/flask/app.py", line 2292, in wsgi_app
    response = self.full_dispatch_request()
  File "/home/ec2-user/.local/lib/python3.7/site-packages/flask/app.py", line 1815, in full_dispatch_request
    rv = self.handle_user_exception(e)
  File "/home/ec2-user/.local/lib/python3.7/site-packages/flask/app.py", line 1718, in handle_user_exception
    reraise(exc_type, exc_value, tb)
  File "/home/ec2-user/.local/lib/python3.7/site-packages/flask/_compat.py", line 35, in reraise
    raise value
  File "/home/ec2-user/.local/lib/python3.7/site-packages/flask/app.py", line 1813, in full_dispatch_request
    rv = self.dispatch_request()
  File "/home/ec2-user/.local/lib/python3.7/site-packages/flask/app.py", line 1799, in dispatch_request
    return self.view_functions[rule.endpoint](**req.view_args)
  File "/home/ec2-user/environment/lihkg/app/main/routes.py", line 47, in casual
    page, current_app.config['POSTS_PER_PAGE'], False)
  File "/home/ec2-user/.local/lib/python3.7/site-packages/flask_sqlalchemy/__init__.py", line 491, in paginate
    items = self.limit(per_page).offset((page - 1) * per_page).all()
  File "/home/ec2-user/.local/lib/python3.7/site-packages/sqlalchemy/orm/query.py", line 2783, in all
    return list(self)
  File "/home/ec2-user/.local/lib/python3.7/site-packages/sqlalchemy/orm/query.py", line 2935, in __iter__
    return self._execute_and_instances(context)
  File "/home/ec2-user/.local/lib/python3.7/site-packages/sqlalchemy/orm/query.py", line 2958, in _execute_and_instances
    result = conn.execute(querycontext.statement, self._params)
  File "/home/ec2-user/.local/lib/python3.7/site-packages/sqlalchemy/engine/base.py", line 948, in execute
    return meth(self, multiparams, params)
  File "/home/ec2-user/.local/lib/python3.7/site-packages/sqlalchemy/sql/elements.py", line 269, in _execute_on_connection
    return connection._execute_clauseelement(self, multiparams, params)
  File "/home/ec2-user/.local/lib/python3.7/site-packages/sqlalchemy/engine/base.py", line 1060, in _execute_clauseelement
    compiled_sql, distilled_params
  File "/home/ec2-user/.local/lib/python3.7/site-packages/sqlalchemy/engine/base.py", line 1200, in _execute_context
    context)
  File "/home/ec2-user/.local/lib/python3.7/site-packages/sqlalchemy/engine/base.py", line 1413, in _handle_dbapi_exception
    exc_info
  File "/home/ec2-user/.local/lib/python3.7/site-packages/sqlalchemy/util/compat.py", line 203, in raise_from_cause
    reraise(type(exception), exception, tb=exc_tb, cause=cause)
  File "/home/ec2-user/.local/lib/python3.7/site-packages/sqlalchemy/util/compat.py", line 186, in reraise
    raise value.with_traceback(tb)
  File "/home/ec2-user/.local/lib/python3.7/site-packages/sqlalchemy/engine/base.py", line 1193, in _execute_context
    context)
  File "/home/ec2-user/.local/lib/python3.7/site-packages/sqlalchemy/engine/default.py", line 508, in do_execute
    cursor.execute(statement, parameters)
sqlalchemy.exc.OperationalError: (sqlite3.OperationalError) no such table: post [SQL: 'SELECT post.id AS post_id, post.title AS post_title, post.body AS post_body, post.timestamp AS post_timestamp, post.category_id AS post_category_id, post.user_id AS post_user_id \nFROM post ORDER BY post.timestamp DESC\n LIMIT ? OFFSET ?'] [parameters: (25, 0)] (Background on this error at: http://sqlalche.me/e/e3q8)
2021-05-01 09:00:33,637 INFO: Microblog startup [in /home/ec2-user/environment/lihkg/app/__init__.py:74]
2021-05-01 09:00:58,356 INFO: Microblog startup [in /home/ec2-user/environment/lihkg/app/__init__.py:74]
2021-05-01 09:07:17,600 INFO: Microblog startup [in /home/ec2-user/environment/lihkg/app/__init__.py:74]
2021-05-01 09:07:24,708 INFO: Microblog startup [in /home/ec2-user/environment/lihkg/app/__init__.py:74]
2021-05-01 09:07:32,866 INFO: Microblog startup [in /home/ec2-user/environment/lihkg/app/__init__.py:74]
2021-05-01 09:08:34,676 INFO: Microblog startup [in /home/ec2-user/environment/lihkg/app/__init__.py:74]
2021-05-01 13:35:33,205 INFO: Microblog startup [in /home/ec2-user/environment/lihkg/app/__init__.py:74]
2021-05-01 13:39:32,332 INFO: Microblog startup [in /home/ec2-user/environment/lihkg/app/__init__.py:74]
2021-05-01 14:10:47,549 INFO: Microblog startup [in /home/ec2-user/environment/lihkg/app/__init__.py:74]
2021-05-01 14:10:54,504 INFO: Microblog startup [in /home/ec2-user/environment/lihkg/app/__init__.py:74]
2021-05-01 14:18:07,258 INFO: Microblog startup [in /home/ec2-user/environment/lihkg/app/__init__.py:74]
2021-05-01 14:18:07,968 INFO: Microblog startup [in /home/ec2-user/environment/lihkg/app/__init__.py:74]
2021-05-01 14:18:35,516 INFO: Microblog startup [in /home/ec2-user/environment/lihkg/app/__init__.py:74]
2021-05-01 14:20:27,736 INFO: Microblog startup [in /home/ec2-user/environment/lihkg/app/__init__.py:74]
2021-05-01 14:25:37,858 INFO: Microblog startup [in /home/ec2-user/environment/lihkg/app/__init__.py:74]
2021-05-01 14:25:39,288 INFO: Microblog startup [in /home/ec2-user/environment/lihkg/app/__init__.py:74]
2021-05-01 14:36:55,289 INFO: Microblog startup [in /home/ec2-user/environment/lihkg/app/__init__.py:74]
2021-05-01 14:49:32,402 INFO: Microblog startup [in /home/ec2-user/environment/lihkg/app/__init__.py:74]
2021-05-01 14:57:03,827 INFO: Microblog startup [in /home/ec2-user/environment/lihkg/app/__init__.py:74]
2021-05-01 14:57:14,644 INFO: Microblog startup [in /home/ec2-user/environment/lihkg/app/__init__.py:74]
2021-05-01 14:57:20,434 INFO: Microblog startup [in /home/ec2-user/environment/lihkg/app/__init__.py:74]
2021-05-01 14:58:44,132 INFO: Microblog startup [in /home/ec2-user/environment/lihkg/app/__init__.py:74]
2021-05-01 14:59:00,114 INFO: Microblog startup [in /home/ec2-user/environment/lihkg/app/__init__.py:74]
2021-05-01 16:05:08,611 INFO: Microblog startup [in /home/ec2-user/environment/lihkg/app/__init__.py:74]
2021-05-01 16:07:41,793 INFO: Microblog startup [in /home/ec2-user/environment/lihkg/app/__init__.py:74]
2021-05-02 02:13:27,806 INFO: Microblog startup [in /home/ec2-user/environment/lihkg/app/__init__.py:74]
2021-05-02 04:47:44,944 INFO: Microblog startup [in /home/ec2-user/environment/lihkg/app/__init__.py:74]
2021-05-02 04:50:27,394 INFO: Microblog startup [in /home/ec2-user/environment/lihkg/app/__init__.py:74]
2021-05-02 04:51:10,215 INFO: Microblog startup [in /home/ec2-user/environment/lihkg/app/__init__.py:74]
2021-05-02 04:52:13,374 INFO: Microblog startup [in /home/ec2-user/environment/lihkg/app/__init__.py:74]
2021-05-02 04:52:34,839 ERROR: Exception on / [GET] [in /home/ec2-user/.local/lib/python3.7/site-packages/flask/app.py:1761]
Traceback (most recent call last):
  File "/home/ec2-user/.local/lib/python3.7/site-packages/flask/app.py", line 2292, in wsgi_app
    response = self.full_dispatch_request()
  File "/home/ec2-user/.local/lib/python3.7/site-packages/flask/app.py", line 1815, in full_dispatch_request
    rv = self.handle_user_exception(e)
  File "/home/ec2-user/.local/lib/python3.7/site-packages/flask/app.py", line 1718, in handle_user_exception
    reraise(exc_type, exc_value, tb)
  File "/home/ec2-user/.local/lib/python3.7/site-packages/flask/_compat.py", line 35, in reraise
    raise value
  File "/home/ec2-user/.local/lib/python3.7/site-packages/flask/app.py", line 1813, in full_dispatch_request
    rv = self.dispatch_request()
  File "/home/ec2-user/.local/lib/python3.7/site-packages/flask/app.py", line 1799, in dispatch_request
    return self.view_functions[rule.endpoint](**req.view_args)
  File "/home/ec2-user/environment/lihkg/app/main/routes.py", line 44, in casual
    session['username'] = 'name'
NameError: name 'session' is not defined
2021-05-02 04:53:21,065 ERROR: Exception on / [GET] [in /home/ec2-user/.local/lib/python3.7/site-packages/flask/app.py:1761]
Traceback (most recent call last):
  File "/home/ec2-user/.local/lib/python3.7/site-packages/flask/app.py", line 2292, in wsgi_app
    response = self.full_dispatch_request()
  File "/home/ec2-user/.local/lib/python3.7/site-packages/flask/app.py", line 1815, in full_dispatch_request
    rv = self.handle_user_exception(e)
  File "/home/ec2-user/.local/lib/python3.7/site-packages/flask/app.py", line 1718, in handle_user_exception
    reraise(exc_type, exc_value, tb)
  File "/home/ec2-user/.local/lib/python3.7/site-packages/flask/_compat.py", line 35, in reraise
    raise value
  File "/home/ec2-user/.local/lib/python3.7/site-packages/flask/app.py", line 1813, in full_dispatch_request
    rv = self.dispatch_request()
  File "/home/ec2-user/.local/lib/python3.7/site-packages/flask/app.py", line 1799, in dispatch_request
    return self.view_functions[rule.endpoint](**req.view_args)
  File "/home/ec2-user/environment/lihkg/app/main/routes.py", line 44, in casual
    page = request.args.get('page', 1, type=int)
NameError: name 'session' is not defined
2021-05-02 04:54:37,832 INFO: Microblog startup [in /home/ec2-user/environment/lihkg/app/__init__.py:74]
2021-05-02 05:09:23,883 INFO: Microblog startup [in /home/ec2-user/environment/lihkg/app/__init__.py:74]
2021-05-02 05:10:49,517 INFO: Microblog startup [in /home/ec2-user/environment/lihkg/app/__init__.py:74]
2021-05-02 05:28:35,717 INFO: Microblog startup [in /home/ec2-user/environment/lihkg/app/__init__.py:74]
